<?xml version="1.0" ?>
<!-- =================================================================================== -->
<!-- |    This document was autogenerated by xacro from irb14000.xacro                 | -->
<!-- |    EDITING THIS FILE BY HAND IS NOT RECOMMENDED                                 | -->
<!-- =================================================================================== -->
<robot name="abb_irb14000" xmlns:xacro="http://www.ros.org/wiki/xacro">
  <!-- Files containing macros and properties for the robot -->
  <!--============================================================================================
  = Main macros
  =============================================================================================-->
  <!-- Basic link macro-->
  <!-- Basic joint macro -->
  <!--============================================
  = Macro for a irb14000 arm
  =============================================-->
  <!--============================================
  = Macro for constructing the IRB14000 robot
  =============================================-->
  <!--============================================================================================
  = Auxiliary macros
  =============================================================================================-->
  <!--============================================
  = Setup all the joints in the left arm
  =============================================-->
  <!--============================================
  = Setup all the joints in the right arm
  =============================================-->
  <!--============================================================================================
  = Properties for the joints in the left arm. Origin, axis and limit values for each joint.
  =============================================================================================-->
  <!-- left_joint_1 -->
  <!-- Length of rotational axis [mm] (for normalization) -->
  <!-- left_joint_2 -->
  <!-- Length of rotational axis [mm] (for normalization) -->
  <!-- left_joint_3 -->
  <!-- Length of rotational axis [mm] (for normalization) -->
  <!-- left_joint_4 -->
  <!-- Length of rotational axis [mm] (for normalization) -->
  <!-- left_joint_5 -->
  <!-- Length of rotational axis [mm] (for normalization) -->
  <!-- left_joint_6 -->
  <!-- Length of rotational axis [mm] (for normalization) -->
  <!-- left_joint_7 -->
  <!-- Length of rotational axis [mm] (for normalization) -->
  <!--============================================================================================
  = Properties for the joints in the right arm. Origin, axis and limit values for each joint.
  =============================================================================================-->
  <!-- right_joint_1 -->
  <!-- Length of rotational axis [mm] (for normalization) -->
  &gt;

  <!-- right_joint_2 -->
  <!-- Length of rotational axis [mm] (for normalization) -->
  <!-- right_joint_3 -->
  <!-- Length of rotational axis [mm] (for normalization) -->
  <!-- right_joint_4 -->
  <!-- Length of rotational axis [mm] (for normalization) -->
  <!-- right_joint_5 -->
  <!-- Length of rotational axis [mm] (for normalization) -->
  <!-- right_joint_6 -->
  <!-- Length of rotational axis [mm] (for normalization) -->
  <!-- right_joint_7 -->
  <!-- Length of rotational axis [mm] (for normalization) -->
  <!--============================================================================================
  = Main macros
  =============================================================================================-->
  <mujoco>
        <compiler meshdir="/home/shahbaz/Research/Software/Spyder_ws/gps/yumi_model/" balanceinertia="true"/>
  </mujoco>
  <!-- Setup the robot -->
  <link name="base_link">
    <visual>
      <geometry>
        <mesh filename="/home/shahbaz/Research/Software/Spyder_ws/gps/yumi_model/base_link_v.stl"/>
      </geometry>
      <origin rpy="0 0 0" xyz="0 0 0"/>
      <material name="gray">
        <color rgba="1.0 1.0 1.0 1.0"/>
      </material>
    </visual>
    <collision>
      <geometry>
        <mesh filename="/home/shahbaz/Research/Software/Spyder_ws/gps/yumi_model/base_link_v.stl"/>
      </geometry>
      <origin rpy="0 0 0" xyz="0 0 0"/>
    </collision>
  </link>
  <!-- Links -->
  <link name="left_link_1">
    <visual>
      <geometry>
        <mesh filename="/home/shahbaz/Research/Software/Spyder_ws/gps/yumi_model/left_link_1_v.stl"/>
      </geometry>
      <origin rpy="0 0 0" xyz="0 0 0"/>
      <material name="gray">
        <color rgba="0.5 0.5 0.5 1.0"/>
      </material>
    </visual>
    <collision>
      <geometry>
        <mesh filename="/home/shahbaz/Research/Software/Spyder_ws/gps/yumi_model/left_link_1_v.stl"/>
      </geometry>
      <origin rpy="0 0 0" xyz="0 0 0"/>
    </collision>
  </link>
  <link name="left_link_2">
    <visual>
      <geometry>
        <mesh filename="/home/shahbaz/Research/Software/Spyder_ws/gps/yumi_model/left_link_2_v.stl"/>
      </geometry>
      <origin rpy="0 0 0" xyz="0 0 0"/>
      <material name="gray">
        <color rgba="1.0 1.0 1.0 1.0"/>
      </material>
    </visual>
    <collision>
      <geometry>
        <mesh filename="/home/shahbaz/Research/Software/Spyder_ws/gps/yumi_model/left_link_2_v.stl"/>
      </geometry>
      <origin rpy="0 0 0" xyz="0 0 0"/>
    </collision>
  </link>
  <link name="left_link_3">
    <visual>
      <geometry>
        <mesh filename="/home/shahbaz/Research/Software/Spyder_ws/gps/yumi_model/left_link_3_v.stl"/>
      </geometry>
      <origin rpy="0 0 0" xyz="0 0 0"/>
      <material name="gray">
        <color rgba="0.5 0.5 0.5 1.0"/>
      </material>
    </visual>
    <collision>
      <geometry>
        <mesh filename="/home/shahbaz/Research/Software/Spyder_ws/gps/yumi_model/left_link_3_v.stl"/>
      </geometry>
      <origin rpy="0 0 0" xyz="0 0 0"/>
    </collision>
  </link>
  <link name="left_link_4">
    <visual>
      <geometry>
        <mesh filename="/home/shahbaz/Research/Software/Spyder_ws/gps/yumi_model/left_link_4_v.stl"/>
      </geometry>
      <origin rpy="0 0 0" xyz="0 0 0"/>
      <material name="gray">
        <color rgba="1.0 1.0 1.0 1.0"/>
      </material>
    </visual>
    <collision>
      <geometry>
        <mesh filename="/home/shahbaz/Research/Software/Spyder_ws/gps/yumi_model/left_link_4_v.stl"/>
      </geometry>
      <origin rpy="0 0 0" xyz="0 0 0"/>
    </collision>
  </link>
  <link name="left_link_5">
    <visual>
      <geometry>
        <mesh filename="/home/shahbaz/Research/Software/Spyder_ws/gps/yumi_model/left_link_5_v.stl"/>
      </geometry>
      <origin rpy="0 0 0" xyz="0 0 0"/>
      <material name="gray">
        <color rgba="0.5 0.5 0.5 1.0"/>
      </material>
    </visual>
    <collision>
      <geometry>
        <mesh filename="/home/shahbaz/Research/Software/Spyder_ws/gps/yumi_model/left_link_5_v.stl"/>
      </geometry>
      <origin rpy="0 0 0" xyz="0 0 0"/>
    </collision>
  </link>
  <link name="left_link_6">
    <visual>
      <geometry>
        <mesh filename="/home/shahbaz/Research/Software/Spyder_ws/gps/yumi_model/left_link_6_v.stl"/>
      </geometry>
      <origin rpy="0 0 0" xyz="0 0 0"/>
      <material name="gray">
        <color rgba="1.0 1.0 1.0 1.0"/>
      </material>
    </visual>
    <collision>
      <geometry>
        <mesh filename="/home/shahbaz/Research/Software/Spyder_ws/gps/yumi_model/left_link_6_v.stl"/>
      </geometry>
      <origin rpy="0 0 0" xyz="0 0 0"/>
    </collision>
  </link>
  <link name="left_link_7">
    <visual>
      <geometry>
        <mesh filename="/home/shahbaz/Research/Software/Spyder_ws/gps/yumi_model/left_link_7_v.stl"/>
      </geometry>
      <origin rpy="0 0 0" xyz="0 0 0"/>
      <material name="gray">
        <color rgba="0.5 0.5 0.5 1.0"/>
      </material>
    </visual>
    <collision>
      <geometry>
        <mesh filename="/home/shahbaz/Research/Software/Spyder_ws/gps/yumi_model/left_link_7_v.stl"/>
      </geometry>
      <origin rpy="0 0 0" xyz="0 0 0"/>
    </collision>
  </link>
  <link name="left_tool0"/>
  <!-- Joints -->
  <joint name="left_joint_1" type="revolute">
    <parent link="base_link"/>
    <child link="left_link_1"/>
    <origin xyz="0.02767                      0.06163                      0.39997"/>
    <!-- <origin xyz="0.0476 0.07 0.4115" rpy="-0.9790814170822807 0.5692132849663647 -0.8254176948094931"/> -->
    <axis xyz="0.813781891                   0.342033376804                   0.469864032781"/>
    <!-- <axis xyz="0                   0                  1"/> -->
    <limit effort="0.0" lower="-2.92342649709" upper="2.92342649709" velocity="3.14159265359"/>
  </joint>
  <joint name="left_joint_2" type="revolute">
    <parent link="left_link_1"/>
    <child link="left_link_2"/>
    <origin xyz="0.09359                      0.08563                      0.0565"/>
    <axis xyz="0.107005805065                   0.706538329704                   -0.699537949934"/>
    <limit effort="0.0" lower="-2.48709418409" upper="0.741764932098" velocity="3.14159265359"/>
  </joint>
  <joint name="left_joint_3" type="revolute">
    <parent link="left_link_2"/>
    <child link="left_link_3"/>
    <origin xyz="0.11922                      0.00381                      0.06637"/>
    <axis xyz="0.813771185903                   0.34206991743                   0.469855982337"/>
    <limit effort="0.0" lower="-2.92342649709" upper="2.92342649709" velocity="3.14159265359"/>
  </joint>
  <joint name="left_joint_4" type="revolute">
    <parent link="left_link_3"/>
    <child link="left_link_4"/>
    <origin xyz="0.12649                      0.0436                      0.00883"/>
    <axis xyz="0.106857471368                   0.706733207183                   -0.699363726399"/>
    <limit effort="0.0" lower="-2.13802833369" upper="1.37881010908" velocity="3.14159265359"/>
  </joint>
  <joint name="left_joint_5" type="revolute">
    <parent link="left_link_4"/>
    <child link="left_link_5"/>
    <origin xyz="0.10366                      -0.09418                      -0.0248"/>
    <axis xyz="0.571257473841                   -0.619307167902                   -0.538631138367"/>
    <limit effort="0.0" lower="-5.04400153826" upper="5.04400153826" velocity="6.98131700798"/>
  </joint>
  <joint name="left_joint_6" type="revolute">
    <parent link="left_link_5"/>
    <child link="left_link_6"/>
    <origin xyz="0.05912                      -0.0626                      -0.11428"/>
    <axis xyz="0.106863251721                   0.706797296472                   -0.699298120913"/>
    <limit effort="0.0" lower="-1.51843644924" upper="2.39110107523" velocity="6.98131700798"/>
  </joint>
  <joint name="left_joint_7" type="revolute">
    <parent link="left_link_6"/>
    <child link="left_link_7"/>
    <origin xyz="0.01635                      -0.01921                      0.04313"/>
    <axis xyz="0.571210480579                   -0.619367006179                   -0.538612217096"/>
    <limit effort="0.0" lower="-3.97935069455" upper="3.97935069455" velocity="6.98131700798"/>
  </joint>
  <joint name="left_joint_7-tool0" type="fixed">
    <origin rpy="-2.22756372432 0.489041256409 -2.74365758414" xyz="0.02173 -0.02341 -0.02059"/>
    <parent link="left_link_7"/>
    <child link="left_tool0"/>
  </joint>
  <!-- Links -->
  <link name="right_link_1">
    <visual>
      <geometry>
        <mesh filename="/home/shahbaz/Research/Software/Spyder_ws/gps/yumi_model/right_link_1_v.stl"/>
      </geometry>
      <origin rpy="0 0 0" xyz="0 0 0"/>
      <material name="gray">
        <color rgba="0.5 0.5 0.5 1.0"/>
      </material>
    </visual>
    <collision>
      <geometry>
        <mesh filename="/home/shahbaz/Research/Software/Spyder_ws/gps/yumi_model/right_link_1_v.stl"/>
      </geometry>
      <origin rpy="0 0 0" xyz="0 0 0"/>
    </collision>
  </link>
  <link name="right_link_2">
    <visual>
      <geometry>
        <mesh filename="/home/shahbaz/Research/Software/Spyder_ws/gps/yumi_model/right_link_2_v.stl"/>
      </geometry>
      <origin rpy="0 0 0" xyz="0 0 0"/>
      <material name="gray">
        <color rgba="1.0 1.0 1.0 1.0"/>
      </material>
    </visual>
    <collision>
      <geometry>
        <mesh filename="/home/shahbaz/Research/Software/Spyder_ws/gps/yumi_model/right_link_2_v.stl"/>
      </geometry>
      <origin rpy="0 0 0" xyz="0 0 0"/>
    </collision>
  </link>
  <link name="right_link_3">
    <visual>
      <geometry>
        <mesh filename="/home/shahbaz/Research/Software/Spyder_ws/gps/yumi_model/right_link_3_v.stl"/>
      </geometry>
      <origin rpy="0 0 0" xyz="0 0 0"/>
      <material name="gray">
        <color rgba="0.5 0.5 0.5 1.0"/>
      </material>
    </visual>
    <collision>
      <geometry>
        <mesh filename="/home/shahbaz/Research/Software/Spyder_ws/gps/yumi_model/right_link_3_v.stl"/>
      </geometry>
      <origin rpy="0 0 0" xyz="0 0 0"/>
    </collision>
  </link>
  <link name="right_link_4">
    <visual>
      <geometry>
        <mesh filename="/home/shahbaz/Research/Software/Spyder_ws/gps/yumi_model/right_link_4_v.stl"/>
      </geometry>
      <origin rpy="0 0 0" xyz="0 0 0"/>
      <material name="gray">
        <color rgba="1.0 1.0 1.0 1.0"/>
      </material>
    </visual>
    <collision>
      <geometry>
        <mesh filename="/home/shahbaz/Research/Software/Spyder_ws/gps/yumi_model/right_link_4_v.stl"/>
      </geometry>
      <origin rpy="0 0 0" xyz="0 0 0"/>
    </collision>
  </link>
  <link name="right_link_5">
    <visual>
      <geometry>
        <mesh filename="/home/shahbaz/Research/Software/Spyder_ws/gps/yumi_model/right_link_5_v.stl"/>
      </geometry>
      <origin rpy="0 0 0" xyz="0 0 0"/>
      <material name="gray">
        <color rgba="0.5 0.5 0.5 1.0"/>
      </material>
    </visual>
    <collision>
      <geometry>
        <mesh filename="/home/shahbaz/Research/Software/Spyder_ws/gps/yumi_model/right_link_5_v.stl"/>
      </geometry>
      <origin rpy="0 0 0" xyz="0 0 0"/>
    </collision>
  </link>
  <link name="right_link_6">
    <visual>
      <geometry>
        <mesh filename="/home/shahbaz/Research/Software/Spyder_ws/gps/yumi_model/right_link_6_v.stl"/>
      </geometry>
      <origin rpy="0 0 0" xyz="0 0 0"/>
      <material name="gray">
        <color rgba="1.0 1.0 1.0 1.0"/>
      </material>
    </visual>
    <collision>
      <geometry>
        <mesh filename="/home/shahbaz/Research/Software/Spyder_ws/gps/yumi_model/right_link_6_v.stl"/>
      </geometry>
      <origin rpy="0 0 0" xyz="0 0 0"/>
    </collision>
  </link>
  <link name="right_link_7">
    <visual>
      <geometry>
        <mesh filename="/home/shahbaz/Research/Software/Spyder_ws/gps/yumi_model/right_link_7_v.stl"/>
      </geometry>
      <origin rpy="0 0 0" xyz="0 0 0"/>
      <material name="gray">
        <color rgba="0.5 0.5 0.5 1.0"/>
      </material>
    </visual>
    <collision>
      <geometry>
        <mesh filename="/home/shahbaz/Research/Software/Spyder_ws/gps/yumi_model/right_link_7_v.stl"/>
      </geometry>
      <origin rpy="0 0 0" xyz="0 0 0"/>
    </collision>
  </link>
  <link name="right_tool0"/>
  <!-- Joints -->
  <joint name="right_joint_1" type="revolute">
    <parent link="base_link"/>
    <child link="right_link_1"/>
    <origin xyz="0.02767                      -0.06163                      0.39997"/>
    <!-- <origin xyz="0.0476 -0.07  0.4115" rpy="0.9791 0.5692 0.8254"/> -->
    <axis xyz="0.813781891                   -0.342033376804                   0.469864032781"/>
    <!-- <axis xyz="0.0                   0.0                   1.0"/> -->
    <limit effort="0.0" lower="-2.92342649709" upper="2.92342649709" velocity="3.14159265359"/>
  </joint>
  <joint name="right_joint_2" type="revolute">
    <parent link="right_link_1"/>
    <child link="right_link_2"/>
    <origin xyz="0.08697                      -0.04182                      0.09986"/>
    <axis xyz="-0.107005805065                   0.706538329704                   0.699537949934"/>
    <limit effort="0.0" lower="-2.48709418409" upper="0.741764932098" velocity="3.14159265359"/>
  </joint>
  <joint name="right_joint_3" type="revolute">
    <parent link="right_link_2"/>
    <child link="right_link_3"/>
    <origin xyz="0.12136                      -0.04574                      0.02043"/>
    <axis xyz="0.813781605313                   -0.342122959735                   0.469799281666"/>
    <limit effort="0.0" lower="-2.92342649709" upper="2.92342649709" velocity="3.14159265359"/>
  </joint>
  <joint name="right_joint_4" type="revolute">
    <parent link="right_link_3"/>
    <child link="right_link_4"/>
    <origin xyz="0.12282                      0.00844                      0.06476"/>
    <axis xyz="-0.106857471368                   0.706733207183                   0.699363726399"/>
    <limit effort="0.0" lower="-2.13802833369" upper="1.37881010908" velocity="3.14159265359"/>
  </joint>
  <joint name="right_joint_5" type="revolute">
    <parent link="right_link_4"/>
    <child link="right_link_5"/>
    <origin xyz="0.11181                      0.04026                      -0.07815"/>
    <axis xyz="0.571257473841                   0.619307167902                   -0.538631138367"/>
    <limit effort="0.0" lower="-5.04400153826" upper="5.04400153826" velocity="6.98131700798"/>
  </joint>
  <joint name="right_joint_6" type="revolute">
    <parent link="right_link_5"/>
    <child link="right_link_6"/>
    <origin xyz="0.04951                      0.12621                      -0.05134"/>
    <axis xyz="-0.106661912593                   0.706635170928                   0.699492632138"/>
    <limit effort="0.0" lower="-1.51843644924" upper="2.39110107523" velocity="6.98131700798"/>
  </joint>
  <joint name="right_joint_7" type="revolute">
    <parent link="right_link_6"/>
    <child link="right_link_7"/>
    <origin xyz="0.02596                      -0.0444                      -0.01981"/>
    <axis xyz="0.571392949531                   0.619383958415                   -0.538399130923"/>
    <limit effort="0.0" lower="-3.97935069455" upper="3.97935069455" velocity="6.98131700798"/>
  </joint>
  <joint name="right_joint_7-tool0" type="fixed">
    <origin rpy="2.22756372432 0.489041256409 2.74365758414" xyz="0.02173 0.02341 -0.02059"/>
    <parent link="right_link_7"/>
    <child link="right_tool0"/>
  </joint>
  <!-- Left hand -->
  <link name="left_gripper_base">
    <visual>
      <geometry>
        <mesh filename="/home/shahbaz/Research/Software/Spyder_ws/gps/yumi_model/smart_gripper_v.stl"/>
      </geometry>
      <origin rpy="0 0 0" xyz="0 0 0"/>
      <material name="gray">
        <color rgba="1.0 1.0 1.0 1.0"/>
      </material>
    </visual>
    <collision>
      <geometry>
        <mesh filename="/home/shahbaz/Research/Software/Spyder_ws/gps/yumi_model/smart_gripper_v.stl"/>
      </geometry>
      <origin rpy="0 0 0" xyz="0 0 0"/>
    </collision>
  </link>
  <joint name="left_gripper_base_joint" type="fixed">
    <parent link="left_tool0"/>
    <child link="left_gripper_base"/>
    <origin xyz="0.0                       0.0                       0.0"/>
  </joint>
  <!-- Right hand -->
  <link name="right_gripper_base">
    <visual>
      <geometry>
        <mesh filename="/home/shahbaz/Research/Software/Spyder_ws/gps/yumi_model/smart_gripper_v.stl"/>
      </geometry>
      <origin rpy="0 0 0" xyz="0 0 0"/>
      <material name="gray">
        <color rgba="1.0 1.0 1.0 1.0"/>
      </material>
    </visual>
    <collision>
      <geometry>
        <mesh filename="/home/shahbaz/Research/Software/Spyder_ws/gps/yumi_model/smart_gripper_v.stl"/>
      </geometry>
      <origin rpy="0 0 0" xyz="0 0 0"/>
    </collision>
  </link>
  <joint name="right_gripper_base_joint" type="fixed">
    <parent link="right_tool0"/>
    <child link="right_gripper_base"/>
    <origin xyz="0.0                       0.0                       0.0"/>
  </joint>
</robot>
