<?xml version="1.0" ?>
<!-- =================================================================================== -->
<!-- |    This document was autogenerated by xacro from yumiABB.urdf.xacro             | -->
<!-- |    EDITING THIS FILE BY HAND IS NOT RECOMMENDED                                 | -->
<!-- =================================================================================== -->
<robot name="yumi" xmlns:xacro="http://www.ros.org/wiki/xacro">

  <!-- Import utilities -->
  <!-- The following macros are adapted from the LWR 4 definitions of the RCPRG - https://github.com/RCPRG-ros-pkg/lwr_robot -->
  <!--Little helper macros to define the inertia matrix needed for links.-->
  <!--Cuboid-->
  <!--Cylinder: length is along the y-axis! -->
  <!--Import the yumi macro -->
  <!-- Import all Gazebo-customization elements, including Gazebo colors -->
  <!-- Import Transmissions -->
  <!-- some constants -->
  <!--Import the yumi servo gripper macro -->
  <!-- Import all Gazebo-customization elements, including Gazebo colors -->
  <!-- Import Transmissions -->
  <!-- some constants -->
  <!-- Import Gazebo plugins -->
    <!--yumi-->
  <link name="yumi_base_link"/>
  <joint name="yumi_base_link_to_body" type="fixed">
    <parent link="yumi_base_link"/>
    <child link="yumi_body"/>
    <origin rpy="0 0 0" xyz="0 0 0"/>
  </joint>
  <link name="yumi_body">
    <inertial>
      <origin rpy="0 0 0" xyz="0 0 0"/>
      <mass value="15"/>
      <inertia ixx="0.5" ixy="0" ixz="0" iyy="0.6" iyz="0" izz="0.3"/>
    </inertial>
    <visual>
      <origin rpy="0 0 0" xyz="0 0 0"/>
      <geometry>
        <mesh filename="/home/shahbaz/Software/mjc_models/meshes/body.stl"/>
      </geometry>
      <material name="Light_Grey"/>
    </visual>
    <collision>
      <origin rpy="0 0 0" xyz="0 0 0"/>
      <geometry>
        <mesh filename="/home/shahbaz/Software/mjc_models/meshes/coarse/body.stl"/>
      </geometry>
      <material name="Light_Grey"/>
    </collision>
  </link>
  <!--///////////////////////////////////// RIGHT ARM ////////////////////////////////  -->
  <!-- joint between body and link_1_r -->
  <joint name="yumi_joint_1_r" type="revolute">
    <parent link="yumi_body"/>
    <child link="yumi_link_1_r"/>
    <origin rpy="0.9791 0.5692 0.8254" xyz="0.0476 -0.07  0.4115"/>
    <axis xyz="0.0                   0.0                   1.0"/>
    <limit effort="10.0" lower="-2.92342649709" upper="2.92342649709" velocity="3.14159265359"/>
    <dynamics damping="1.06" friction="2.43"/>
  </joint>
  <link name="yumi_link_1_r">
    <inertial>
      <origin rpy="0 0 0" xyz="-0.01468 -0.00021 0.06646"/>
      <mass value="1.753"/>
      <inertia ixx="0.00561" ixy="0.000101" ixz="-0.00113" iyy="0.00545" iyz="-0.000180" izz="0.00289"/>
    </inertial>
    <visual>
      <origin rpy="0 0 0" xyz="0 0 0"/>
      <geometry>
        <mesh filename="/home/shahbaz/Software/mjc_models/meshes/link_1.stl"/>
      </geometry>
      <material name="Grey"/>
    </visual>
    <collision>
      <origin rpy="0 0 0" xyz="0 0 0"/>
      <geometry>
        <mesh filename="/home/shahbaz/Software/mjc_models/meshes/coarse/link_1.stl"/>
      </geometry>
      <material name="Grey"/>
    </collision>
  </link>
  <!-- joint between link_1_r and link_2_r -->
  <joint name="yumi_joint_2_r" type="revolute">
    <parent link="yumi_link_1_r"/>
    <child link="yumi_link_2_r"/>
    <origin xyz="-0.03            0                      0.1075"/>
    <axis xyz="0.0                   1.0                  0.0"/>
    <limit effort="10.0" lower="-2.48709418409" upper="0.741764932098" velocity="3.14159265359"/>
    <dynamics damping="1.09" friction="2.76"/>
  </joint>
  <link name="yumi_link_2_r">
    <inertial>
      <mass value="1.444"/>
      <origin rpy="0 0 0" xyz="0.01828 -0.0177 0.06202"/>
      <inertia ixx="0.00743" ixy="0.000359" ixz="0.00106" iyy="0.00718" iyz="0.000143" izz="0.00225"/>
    </inertial>
    <visual>
      <origin rpy="0 0 0" xyz="0 0 0"/>
      <geometry>
        <mesh filename="/home/shahbaz/Software/mjc_models/meshes/link_2.stl"/>
      </geometry>
      <material name="Grey"/>
    </visual>
    <collision>
      <origin rpy="0 0 0" xyz="0 0 0"/>
      <geometry>
        <mesh filename="/home/shahbaz/Software/mjc_models/meshes/coarse/link_2.stl"/>
      </geometry>
      <material name="Grey"/>
    </collision>
  </link>
  <!-- joint between link_2_r and link_3_r -->
  <joint name="yumi_joint_7_r" type="revolute">
    <parent link="yumi_link_2_r"/>
    <child link="yumi_link_3_r"/>
    <origin xyz="0.03            0                      0.1603"/>
    <axis xyz="0.0 0.0 1.0"/>
    <limit effort="10.0" lower="-2.92342649709" upper="2.92342649709" velocity="3.14159265359"/>
    <dynamics damping="0.61" friction="1.11"/>
  </joint>
  <link name="yumi_link_3_r">
    <inertial>
      <mass value="0.936"/>
      <origin rpy="0 0 0" xyz="0.02349 0.00556 0.05944"/>
      <inertia ixx="0.00251" ixy="0.00000263" ixz="0.000688" iyy="0.00241" iyz="0.000089" izz="0.00143"/>
    </inertial>
    <visual>
      <origin rpy="0 0 0" xyz="0 0 0"/>
      <geometry>
        <mesh filename="/home/shahbaz/Software/mjc_models/meshes/link_3.stl"/>
      </geometry>
      <material name="Grey"/>
    </visual>
    <collision>
      <origin rpy="0 0 0" xyz="0 0 0"/>
      <geometry>
        <mesh filename="/home/shahbaz/Software/mjc_models/meshes/coarse/link_3.stl"/>
      </geometry>
      <material name="Grey"/>
    </collision>
  </link>
  <!-- joint between link_3_r and link_4_r -->
  <joint name="yumi_joint_3_r" type="revolute">
    <parent link="yumi_link_3_r"/>
    <child link="yumi_link_4_r"/>
    <origin rpy="1.57079632679 -1.57079632679 0.0" xyz="-0.04188 0.0 0.07873"/>
    <axis xyz="0 0 1"/>
    <limit effort="300" lower="-2.15548162621" upper="1.3962634016" velocity="3.14159265359"/>
    <dynamics damping="0.08" friction="0.52"/>
  </joint>
  <link name="yumi_link_4_r">
    <inertial>
      <mass value="0.723"/>
      <origin rpy="0 0 0" xyz="0.05385 -0.01612 0.02336"/>
      <inertia ixx="0.00108" ixy="0.000575" ixz="0.000633" iyy="0.00277" iyz="0.000203" izz="0.00280"/>
    </inertial>
    <visual>
      <origin rpy="0 0 0" xyz="0 0 0"/>
      <geometry>
        <mesh filename="/home/shahbaz/Software/mjc_models/meshes/link_4.stl"/>
      </geometry>
      <material name="Grey"/>
    </visual>
    <collision>
      <origin rpy="0 0 0" xyz="0 0 0"/>
      <geometry>
        <mesh filename="/home/shahbaz/Software/mjc_models/meshes/coarse/link_4.stl"/>
      </geometry>
      <material name="Grey"/>
    </collision>
  </link>
  <!-- joint between link_4_r and link_5_r -->
  <joint name="yumi_joint_4_r" type="revolute">
    <parent link="yumi_link_4_r"/>
    <child link="yumi_link_5_r"/>
    <origin xyz="0.1396 0.0 0.0405"/>
    <axis xyz="1.0 0.0 0.0"/>
    <limit effort="10.0" lower="-5.04400153826" upper="5.04400153826" velocity="6.98131700798"/>
    <dynamics damping="0.08" friction="0.52"/>
  </joint>
  <link name="yumi_link_5_r">
    <inertial>
      <mass value="0.330"/>
      <origin rpy="0 0 0" xyz="0.04991 0.0157 -0.00572"/>
      <inertia ixx="0.000279" ixy="0.000226" ixz="-0.000111" iyy="0.000797" iyz="-0.00002779" izz="0.000867"/>
    </inertial>
    <visual>
      <origin rpy="0 0 0" xyz="0 0 0"/>
      <geometry>
        <mesh filename="/home/shahbaz/Software/mjc_models/meshes/link_5.stl"/>
      </geometry>
      <material name="Grey"/>
    </visual>
    <collision>
      <origin rpy="0 0 0" xyz="0 0 0"/>
      <geometry>
        <mesh filename="/home/shahbaz/Software/mjc_models/meshes/coarse/link_5.stl"/>
      </geometry>
      <material name="Grey"/>
    </collision>
  </link>
  <!-- joint between link_5_r and link_6_r -->
  <joint name="yumi_joint_5_r" type="revolute">
    <parent link="yumi_link_5_r"/>
    <child link="yumi_link_6_r"/>
    <origin xyz="0.1254 0.0 -0.027"/>
    <axis xyz="0.0                   1.0                  0.0"/>
    <limit effort="10.0" lower="-1.51843644924" upper="2.39110107523" velocity="6.98131700798"/>
    <dynamics damping="0.08" friction="0.52"/>
  </joint>
  <link name="yumi_link_6_r">
    <inertial>
      <mass value="0.357"/>
      <origin rpy="0 0 0" xyz="-0.00923 -0.00415 0.0106"/>
      <inertia ixx="0.000298" ixy="-0.00000785" ixz="-0.0000247" iyy="0.000284" iyz="0.0000131" izz="0.000292"/>
    </inertial>
    <visual>
      <origin rpy="0 0 0" xyz="0 0 0"/>
      <geometry>
        <mesh filename="/home/shahbaz/Software/mjc_models/meshes/link_6.stl"/>
      </geometry>
      <material name="Grey"/>
    </visual>
    <collision>
      <origin rpy="0 0 0" xyz="0 0 0"/>
      <geometry>
        <mesh filename="/home/shahbaz/Software/mjc_models/meshes/coarse/link_6.stl"/>
      </geometry>
      <material name="Grey"/>
    </collision>
  </link>
  <!-- joint between link_6_r and link_7_r -->
  <joint name="yumi_joint_6_r" type="revolute">
    <parent link="yumi_link_6_r"/>
    <child link="yumi_link_7_r"/>
    <origin xyz="0.036 0.0 0.027"/>
    <axis xyz="1.0 0.0 0.0"/>
    <limit effort="10.0" lower="-3.97935069455" upper="3.97935069455" velocity="6.98131700798"/>
    <!-- <dynamics damping="0.52" friction="1.0"/> -->
    <dynamics damping="0.1" friction="1.0"/>
  </joint>
  <link name="yumi_link_7_r">
    <inertial>
      <mass value="0.072"/>
      <origin rpy="0 0 0" xyz="-0.01667 -0.00147 0.00026"/>
      <inertia ixx="0.0000201" ixy="0.00000262" ixz="-0.000000481" iyy="0.0000295" iyz="0.000000413" izz="0.0000279"/>
    </inertial>
    <visual>
      <origin rpy="0 0 0" xyz="0 0 0"/>
      <geometry>
        <mesh filename="/home/shahbaz/Software/mjc_models/meshes/link_7.stl"/>
      </geometry>
      <material name="Grey"/>
    </visual>
    <collision>
      <origin rpy="0 0 0" xyz="0 0 0"/>
      <geometry>
        <mesh filename="/home/shahbaz/Software/mjc_models/meshes/coarse/link_7.stl"/>
      </geometry>
      <material name="Grey"/>
    </collision>
  </link>
  <!--///////////////////////////////////// LEFT ARM ////////////////////////////////  -->
  <!-- joint between body and link_1_l -->
  <joint name="yumi_joint_1_l" type="revolute">
    <parent link="yumi_body"/>
    <child link="yumi_link_1_l"/>
    <origin rpy="-0.9790814170822807 0.5692132849663647 -0.8254176948094931" xyz="0.0476 0.07  0.4115"/>
    <axis xyz="0.0                   0.0                   1.0"/>
    <limit effort="10.0" lower="-2.92342649709" upper="2.92342649709" velocity="3.14159265359"/>
    <dynamics damping="1.06" friction="2.43"/>
    <!-- <dynamics damping="1.06" friction="2.43"/> -->
  </joint>
  <link name="yumi_link_1_l">
    <inertial>
      <origin rpy="0 0 0" xyz="-0.01468 -0.00021 0.06646"/>
      <mass value="1.753"/>
      <inertia ixx="0.00561" ixy="0.000101" ixz="-0.00113" iyy="0.00545" iyz="-0.000180" izz="0.00289"/>
    </inertial>
    <visual>
      <origin rpy="0 0 0" xyz="0 0 0"/>
      <geometry>
        <mesh filename="/home/shahbaz/Software/mjc_models/meshes/link_1.stl"/>
      </geometry>
      <material name="Grey"/>
    </visual>
    <collision>
      <origin rpy="0 0 0" xyz="0 0 0"/>
      <geometry>
        <mesh filename="/home/shahbaz/Software/mjc_models/meshes/coarse/link_1.stl"/>
      </geometry>
      <material name="Grey"/>
    </collision>
  </link>
  <!-- joint between link_1_l and link_2_l -->
  <joint name="yumi_joint_2_l" type="revolute">
    <parent link="yumi_link_1_l"/>
    <child link="yumi_link_2_l"/>
    <origin xyz="-0.03            0                      0.1075"/>
    <axis xyz="0.0                   1.0                  0.0"/>
    <limit effort="10.0" lower="-2.48709418409" upper="0.741764932098" velocity="3.14159265359"/>
    <!-- <dynamics damping="1.09" friction="2.76"/> -->
    <dynamics damping="1.09" friction="2.76"/>
  </joint>
  <link name="yumi_link_2_l">
    <inertial>
      <mass value="1.444"/>
      <origin rpy="0 0 0" xyz="0.01828 -0.0177 0.06202"/>
      <inertia ixx="0.00743" ixy="0.000359" ixz="0.00106" iyy="0.00718" iyz="0.000143" izz="0.00225"/>
    </inertial>
    <visual>
      <origin rpy="0 0 0" xyz="0 0 0"/>
      <geometry>
        <mesh filename="/home/shahbaz/Software/mjc_models/meshes/link_2.stl"/>
      </geometry>
      <material name="Grey"/>
    </visual>
    <collision>
      <origin rpy="0 0 0" xyz="0 0 0"/>
      <geometry>
        <mesh filename="/home/shahbaz/Software/mjc_models/meshes/coarse/link_2.stl"/>
      </geometry>
      <material name="Grey"/>
    </collision>
  </link>
  <!-- joint between link_2_l and link_3_l -->
  <joint name="yumi_joint_7_l" type="revolute">
    <parent link="yumi_link_2_l"/>
    <child link="yumi_link_3_l"/>
    <origin xyz="0.03            0                      0.1603"/>
    <axis xyz="0.0 0.0 1.0"/>
    <limit effort="10.0" lower="-2.92342649709" upper="2.92342649709" velocity="3.14159265359"/>
    <!-- <dynamics damping="0.61" friction="1.11"/> -->
    <dynamics damping="0.61" friction="1.11"/>
  </joint>
  <link name="yumi_link_3_l">
    <inertial>
      <mass value="0.936"/>
      <origin rpy="0 0 0" xyz="0.02349 0.00556 0.05944"/>
      <inertia ixx="0.00251" ixy="0.00000263" ixz="0.000688" iyy="0.00241" iyz="0.000089" izz="0.00143"/>
    </inertial>
    <visual>
      <origin rpy="0 0 0" xyz="0 0 0"/>
      <geometry>
        <mesh filename="/home/shahbaz/Software/mjc_models/meshes/link_3.stl"/>
      </geometry>
      <material name="Grey"/>
    </visual>
    <collision>
      <origin rpy="0 0 0" xyz="0 0 0"/>
      <geometry>
        <mesh filename="/home/shahbaz/Software/mjc_models/meshes/coarse/link_3.stl"/>
      </geometry>
      <material name="Grey"/>
    </collision>
  </link>
  <!-- joint between link_3_l and link_4_l -->
  <joint name="yumi_joint_3_l" type="revolute">
    <parent link="yumi_link_3_l"/>
    <child link="yumi_link_4_l"/>
    <origin xyz="0.0405                      0.0                      0.0912"/>
    <axis xyz="0.0                   1.0                  0.0"/>
    <limit effort="10.0" lower="-2.13802833369" upper="1.37881010908" velocity="3.14159265359"/>
    <!-- <dynamics damping="0.08" friction="0.52"/> -->
    <dynamics damping="0.08" friction="0.52"/>
  </joint>
  <link name="yumi_link_4_l">
    <inertial>
      <mass value="0.723"/>
      <origin rpy="0 0 0" xyz="0.05385 -0.01612 0.02336"/>
      <inertia ixx="0.00108" ixy="0.000575" ixz="0.000633" iyy="0.00277" iyz="0.000203" izz="0.00280"/>
    </inertial>
    <visual>
      <origin rpy="0 0 0" xyz="0 0 0"/>
      <geometry>
        <mesh filename="/home/shahbaz/Software/mjc_models/meshes/link_4.stl"/>
      </geometry>
      <material name="Grey"/>
    </visual>
    <collision>
      <origin rpy="0 0 0" xyz="0 0 0"/>
      <geometry>
        <mesh filename="/home/shahbaz/Software/mjc_models/meshes/coarse/link_4.stl"/>
      </geometry>
      <material name="Grey"/>
    </collision>
  </link>
  <!-- joint between link_4_l and link_5_l -->
  <joint name="yumi_joint_4_l" type="revolute">
    <parent link="yumi_link_4_l"/>
    <child link="yumi_link_5_l"/>
    <origin xyz="0.1396 0.0 0.0405"/>
    <axis xyz="1.0 0.0 0.0"/>
    <limit effort="10.0" lower="-5.04400153826" upper="5.04400153826" velocity="6.98131700798"/>
    <!-- <dynamics damping="0.08" friction="0.52"/> -->
    <dynamics damping="0.08" friction="0.52"/>
  </joint>
  <link name="yumi_link_5_l">
    <inertial>
      <mass value="0.330"/>
      <origin rpy="0 0 0" xyz="0.04991 0.0157 -0.00572"/>
      <inertia ixx="0.000279" ixy="0.000226" ixz="-0.000111" iyy="0.000797" iyz="-0.00002779" izz="0.000867"/>
    </inertial>
    <visual>
      <origin rpy="0 0 0" xyz="0 0 0"/>
      <geometry>
        <mesh filename="/home/shahbaz/Software/mjc_models/meshes/link_5.stl"/>
      </geometry>
      <material name="Grey"/>
    </visual>
    <collision>
      <origin rpy="0 0 0" xyz="0 0 0"/>
      <geometry>
        <mesh filename="/home/shahbaz/Software/mjc_models/meshes/coarse/link_5.stl"/>
      </geometry>
      <material name="Grey"/>
    </collision>
  </link>
  <!-- joint between link_5_l and link_6_l -->
  <joint name="yumi_joint_5_l" type="revolute">
    <parent link="yumi_link_5_l"/>
    <child link="yumi_link_6_l"/>
    <origin xyz="0.1254 0.0 -0.027"/>
    <axis xyz="0.0                   1.0                  0.0"/>
    <limit effort="10.0" lower="-1.51843644924" upper="2.39110107523" velocity="6.98131700798"/>
    <!-- <dynamics damping="0.08" friction="0.52"/> -->
    <dynamics damping="0.08" friction="0.52"/>
  </joint>
  <link name="yumi_link_6_l">
    <inertial>
      <mass value="0.357"/>
      <origin rpy="0 0 0" xyz="-0.00923 -0.00415 0.0106"/>
      <inertia ixx="0.000298" ixy="-0.00000785" ixz="-0.0000247" iyy="0.000284" iyz="0.0000131" izz="0.000292"/>
    </inertial>
    <visual>
      <origin rpy="0 0 0" xyz="0 0 0"/>
      <geometry>
        <mesh filename="/home/shahbaz/Software/mjc_models/meshes/link_6.stl"/>
      </geometry>
      <material name="Grey"/>
    </visual>
    <collision>
      <origin rpy="0 0 0" xyz="0 0 0"/>
      <geometry>
        <mesh filename="/home/shahbaz/Software/mjc_models/meshes/coarse/link_6.stl"/>
      </geometry>
      <material name="Grey"/>
    </collision>
  </link>
  <!-- joint between link_6_l and link_7_l -->
  <joint name="yumi_joint_6_l" type="revolute">
    <parent link="yumi_link_6_l"/>
    <child link="yumi_link_7_l"/>
    <origin xyz="0.036 0.0 0.027"/>
    <axis xyz="1.0 0.0 0.0"/>
    <limit effort="10.0" lower="-3.97935069455" upper="3.97935069455" velocity="6.98131700798"/>
    <!-- <dynamics damping="0.52" friction="1.0"/> -->
    <dynamics damping="0.1" friction="1.0"/>
  </joint>
  <link name="yumi_link_7_l">
    <inertial>
      <mass value="0.072"/>
      <origin rpy="0 0 0" xyz="-0.01667 -0.00147 0.00026"/>
      <inertia ixx="0.0000201" ixy="0.00000262" ixz="-0.000000481" iyy="0.0000295" iyz="0.000000413" izz="0.0000279"/>
    </inertial>
    <visual>
      <origin rpy="0 0 0" xyz="0 0 0"/>
      <geometry>
        <mesh filename="/home/shahbaz/Software/mjc_models/meshes/link_7.stl"/>
      </geometry>
      <material name="Grey"/>
    </visual>
    <collision>
      <origin rpy="0 0 0" xyz="0 0 0"/>
      <geometry>
        <mesh filename="/home/shahbaz/Software/mjc_models/meshes/coarse/link_7.stl"/>
      </geometry>
      <material name="Grey"/>
    </collision>
  </link>

  <!--right gripper-->
  <!--joint between {parent} and base-->
  <joint name="yumi_link_7_r_joint" type="fixed">
    <origin rpy="0 0 0" xyz="0.005 0 0"/>
    <parent link="yumi_link_7_r"/>
    <child link="gripper_r_base"/>
  </joint>
  <link name="gripper_r_base">
    <inertial>
      <origin rpy="0 0 0" xyz="0 0 0"/>
      <mass value="0.2"/>
      <inertia ixx="0.0001" ixy="0" ixz="0" iyy="0.0001" iyz="0" izz="0.0001"/>
    </inertial>
    <visual>
      <origin rpy="0 0 0" xyz="0 0 0"/>
      <geometry>
        <mesh filename="/home/shahbaz/Software/mjc_models/meshes/gripper/base.stl"/>
      </geometry>
      <material name="Light_Grey"/>
    </visual>
    <collision>
      <origin rpy="0 0 0" xyz="0 0 0"/>
      <geometry>
        <mesh filename="/home/shahbaz/Software/mjc_models/meshes/gripper/coarse/base.stl"/>
      </geometry>
      <material name="Light_Grey"/>
    </collision>
  </link>
  <!-- joint between base and right finger -->
  <joint name="gripper_r_joint" type="prismatic">
    <parent link="gripper_r_base"/>
    <child link="gripper_r_finger_r"/>
    <origin rpy="0 0 0" xyz="0 -0.0065 0.0837"/>
    <axis xyz="-1 0 0"/>
    <limit effort="20" lower="0" upper="0.025" velocity="2"/>
    <dynamics damping="1.0"/>
  </joint>
  <link name="gripper_r_finger_r">
    <inertial>
      <origin rpy="0 0 0" xyz="0 0 0"/>
      <mass value="0.01"/>
      <inertia ixx="0.000001" ixy="0" ixz="0" iyy="0.000001" iyz="0" izz="0.000001"/>
    </inertial>
    <visual>
      <origin rpy="0 0 0" xyz="0 0 0"/>
      <geometry>
        <mesh filename="/home/shahbaz/Software/mjc_models/meshes/gripper/finger.stl"/>
      </geometry>
      <material name="Blue"/>
    </visual>
    <collision>
      <origin rpy="0 0 0" xyz="0 0 0"/>
      <geometry>
        <mesh filename="/home/shahbaz/Software/mjc_models/meshes/gripper/coarse/finger.stl"/>
      </geometry>
      <material name="Blue"/>
    </collision>
  </link>
  <!-- joint between base and left finger -->
  <joint name="gripper_r_joint_m" type="prismatic">
    <parent link="gripper_r_base"/>
    <child link="gripper_r_finger_l"/>
    <origin rpy="0 0 3.14159265359" xyz="0 0.0065 0.0837"/>
    <axis xyz="-1 0 0"/>
    <limit effort="20" lower="0" upper="0.025" velocity="2"/>
    <dynamics damping="1.0"/>
    <mimic joint="gripper_r_joint"/>
  </joint>
  <link name="gripper_r_finger_l">
    <inertial>
      <origin rpy="0 0 0" xyz="0 0 0"/>
      <mass value="0.01"/>
      <inertia ixx="0.000001" ixy="0" ixz="0" iyy="0.000001" iyz="0" izz="0.000001"/>
    </inertial>
    <visual>
      <origin rpy="0 0 0" xyz="0 0 0"/>
      <geometry>
        <mesh filename="/home/shahbaz/Software/mjc_models/meshes/gripper/finger.stl"/>
      </geometry>
      <material name="Blue"/>
    </visual>
    <collision>
      <origin rpy="0 0 0" xyz="0 0 0"/>
      <geometry>
        <mesh filename="/home/shahbaz/Software/mjc_models/meshes/gripper/coarse/finger.stl"/>
      </geometry>
      <material name="Blue"/>
    </collision>
  </link>

  <!--left gripper-->
  <!--joint between {parent} and base-->
  <joint name="yumi_link_7_l_joint" type="fixed">
    <origin rpy="0 0 0" xyz="0.005 0 0"/>
    <parent link="yumi_link_7_l"/>
    <child link="gripper_l_base"/>
  </joint>
  <link name="gripper_l_base">
    <inertial>
      <origin rpy="0 0 0" xyz="0 0 0"/>
      <mass value="0.2"/>
      <inertia ixx="0.0001" ixy="0" ixz="0" iyy="0.0001" iyz="0" izz="0.0001"/>
    </inertial>
    <visual>
      <origin rpy="0 0 0" xyz="0 0 0"/>
      <geometry>
        <mesh filename="/home/shahbaz/Software/mjc_models/meshes/gripper/base.stl"/>
      </geometry>
      <material name="Light_Grey"/>
    </visual>
    <collision>
      <origin rpy="0 0 0" xyz="0 0 0"/>
      <geometry>
        <mesh filename="/home/shahbaz/Software/mjc_models/meshes/gripper/coarse/base.stl"/>
      </geometry>
      <material name="Light_Grey"/>
    </collision>
  </link>
  <!-- joint between base and right finger -->
  <joint name="gripper_l_joint" type="prismatic">
    <parent link="gripper_l_base"/>
    <child link="gripper_l_finger_r"/>
    <origin rpy="0 0 0" xyz="0 -0.0065 0.0837"/>
    <axis xyz="-1 0 0"/>
    <limit effort="20" lower="0" upper="0.025" velocity="2"/>
    <dynamics damping="1.0"/>
  </joint>
  <link name="gripper_l_finger_r">
    <inertial>
      <origin rpy="0 0 0" xyz="0 0 0"/>
      <mass value="0.01"/>
      <inertia ixx="0.000001" ixy="0" ixz="0" iyy="0.000001" iyz="0" izz="0.000001"/>
    </inertial>
    <visual>
      <origin rpy="0 0 0" xyz="0 0 0"/>
      <geometry>
        <mesh filename="/home/shahbaz/Software/mjc_models/meshes/gripper/finger.stl"/>
      </geometry>
      <material name="Blue"/>
    </visual>
    <collision>
      <origin rpy="0 0 0" xyz="0 0 0"/>
      <geometry>
        <mesh filename="/home/shahbaz/Software/mjc_models/meshes/gripper/coarse/finger.stl"/>
      </geometry>
      <material name="Blue"/>
    </collision>
  </link>
  <!-- joint between base and left finger -->
  <joint name="gripper_l_joint_m" type="prismatic">
    <parent link="gripper_l_base"/>
    <child link="gripper_l_finger_l"/>
    <origin rpy="0 0 3.14159265359" xyz="0 0.0065 0.0837"/>
    <axis xyz="-1 0 0"/>
    <limit effort="20" lower="0" upper="0.025" velocity="2"/>
    <dynamics damping="1.0"/>
    <mimic joint="gripper_l_joint"/>
  </joint>
  <link name="gripper_l_finger_l">
    <inertial>
      <origin rpy="0 0 0" xyz="0 0 0"/>
      <mass value="0.01"/>
      <inertia ixx="0.000001" ixy="0" ixz="0" iyy="0.000001" iyz="0" izz="0.000001"/>
    </inertial>
    <visual>
      <origin rpy="0 0 0" xyz="0 0 0"/>
      <geometry>
        <mesh filename="/home/shahbaz/Software/mjc_models/meshes/gripper/finger.stl"/>
      </geometry>
      <material name="Blue"/>
    </visual>
    <collision>
      <origin rpy="0 0 0" xyz="0 0 0"/>
      <geometry>
        <mesh filename="/home/shahbaz/Software/mjc_models/meshes/gripper/coarse/finger.stl"/>
      </geometry>
      <material name="Blue"/>
    </collision>
  </link>

  <link name="left_contact_point">
  </link>
  <joint name="left_contact_point_joint" type="fixed">
    <parent link="gripper_l_base"/>
    <child link="left_contact_point"/>
    <origin xyz="0.2                       0.0                       0.0"/>
    <!-- <origin xyz="0.0                       0.0                       0"/> -->
  </joint>

  <link name="world"/>
  <joint name="world_joint" type="fixed">
    <parent link="world"/>
    <child link="yumi_base_link"/>
    <origin rpy="0 0 0" xyz="0 0 0.1"/>
  </joint>
</robot>
