<?xml version="1.0" ?>
<!-- =================================================================================== -->
<!-- |    This document was autogenerated by xacro from irb14000.xacro                 | -->
<!-- |    EDITING THIS FILE BY HAND IS NOT RECOMMENDED                                 | -->
<!-- =================================================================================== -->
<robot name="abb_irb14000" xmlns:xacro="http://www.ros.org/wiki/xacro">

  <!-- ***************** Setup the robot ***************** -->

  <!-- ***************** Base Link ****************** -->
  <!-- <mujoco>
        <compiler meshdir="/home/shahbaz/Research/Software/Spyder_ws/gps/yumi_model/" balanceinertia="true"/>
        <option gravity="0.0 0.0 0.0" />
  </mujoco> -->
  <link name="base_link">
    <visual>
      <geometry>
        <mesh filename="/home/shahbaz/Research/Software/Spyder_ws/gps/yumi_model/base_link_v.stl"/>
      </geometry>
      <origin rpy="0 0 0" xyz="0 0 0"/>
      <material name="gray">
        <color rgba="0.5 0.5 0.5 1.0"/>
      </material>
    </visual>
    <collision>
      <geometry>
        <mesh filename="/home/shahbaz/Research/Software/Spyder_ws/gps/yumi_model/base_link_v.stl"/>
      </geometry>
      <origin rpy="0 0 0" xyz="0 0 0"/>
    </collision>
  </link>

  <!-- Right arm -->
  <link name="right_link_1">

    <visual>
      <geometry>
        <mesh filename="/home/shahbaz/Research/Software/Spyder_ws/gps/yumi_model/right_arm/right_link_1_v.stl"/>
      </geometry>
      <origin rpy="0 0 0" xyz="0 0 0"/>
      <material name="gray">
        <color rgba="0.5 0.5 0.5 1.0"/>
      </material>
    </visual>

    <collision>
      <geometry>
        <mesh filename="/home/shahbaz/Research/Software/Spyder_ws/gps/yumi_model/right_arm/right_link_1_v.stl"/>
      </geometry>
      <!-- <origin rpy="0 0 0" xyz="0 0 0"/> -->
      <!-- <origin rpy="0 0 0" xyz="-0.01993 0.00837 -0.01153"/> -->
      <!-- <origin rpy="-0.18425132041591932 -0.9506628417679347 -0.6292507964459597" xyz="-0.01993 0.00837 -0.01153"/> -->
      <origin rpy="-0.18425132041591932 -0.9506628417679347 -0.6292507964459597" xyz="-0.01993 0.00837 -0.01153"/>
    </collision>

    <inertial>
	  <origin xyz="-0.01468 -0.00021 0.06646" rpy="0 0 0"/>
      <mass value="1.753"/>
      <inertia ixx="0.00561" ixy="0.000101" ixz="-0.00113" iyy="0.00545" iyz="-0.000180" izz="0.00289"/>
    </inertial>

  </link>

<link name="right_link_2">
    <visual>
      <geometry>
        <mesh filename="/home/shahbaz/Research/Software/Spyder_ws/gps/yumi_model/right_arm/right_link_2_v.stl"/>
      </geometry>
      <origin rpy="0 0 0" xyz="0 0 0"/>
      <material name="gray">
        <color rgba="0.5 0.5 0.5 1.0"/>
      </material>
    </visual>
    <collision>
      <geometry>
        <mesh filename="/home/shahbaz/Research/Software/Spyder_ws/gps/yumi_model/right_arm/right_link_2_v.stl"/>
      </geometry>
      <origin rpy="0 0 0" xyz="0 0 0"/>
    </collision>

    <inertial>
      <mass value="1.444"/>
      <origin xyz="0.01828 -0.0177 0.06202" rpy="0 0 0"/>
      <inertia ixx="0.00743" ixy="0.000359" ixz="0.00106" iyy="0.00718" iyz="0.000143" izz="0.00225"/>
    </inertial>

  </link>


  <link name="right_link_3">
    <visual>
      <geometry>
        <mesh filename="/home/shahbaz/Research/Software/Spyder_ws/gps/yumi_model/right_arm/right_link_3_v.stl"/>
      </geometry>
      <origin rpy="0 0 0" xyz="0 0 0"/>
      <material name="gray">
        <color rgba="0.5 0.5 0.5 1.0"/>
      </material>
    </visual>
    <collision>
      <geometry>
        <mesh filename="/home/shahbaz/Research/Software/Spyder_ws/gps/yumi_model/right_arm/right_link_3_v.stl"/>
      </geometry>
      <origin rpy="0 0 0" xyz="0 0 0"/>
    </collision>

    <inertial>
      <mass value="0.936"/>
      <origin xyz="0.02349 0.00556 0.05944" rpy="0 0 0"/>
      <inertia ixx="0.00251" ixy="0.00000263" ixz="0.000688" iyy="0.00241" iyz="0.000089" izz="0.00143"/>
    </inertial>

  </link>

  <link name="right_link_4">

    <visual>
      <geometry>
        <mesh filename="/home/shahbaz/Research/Software/Spyder_ws/gps/yumi_model/right_arm/right_link_4_v.stl"/>
      </geometry>
      <origin rpy="0 0 0" xyz="0 0 0"/>
      <material name="gray">
        <color rgba="0.5 0.5 0.5 1.0"/>
      </material>
    </visual>

    <collision>
      <geometry>
        <mesh filename="/home/shahbaz/Research/Software/Spyder_ws/gps/yumi_model/right_arm/right_link_4_v.stl"/>
      </geometry>
      <origin rpy="0 0 0" xyz="0 0 0"/>
    </collision>

    <inertial>
      <mass value="0.723"/>
      <origin xyz="0.05385 -0.01612 0.02336" rpy="0 0 0"/>
      <inertia ixx="0.00108" ixy="0.000575" ixz="0.000633" iyy="0.00277" iyz="0.000203" izz="0.00280"/>
    </inertial>

  </link>

  <link name="right_link_5">
    <visual>
      <geometry>
        <mesh filename="/home/shahbaz/Research/Software/Spyder_ws/gps/yumi_model/right_arm/right_link_5_v.stl"/>
      </geometry>
      <origin rpy="0 0 0" xyz="0 0 0"/>
      <material name="gray">
        <color rgba="0.5 0.5 0.5 1.0"/>
      </material>
    </visual>
    <collision>
      <geometry>
        <mesh filename="/home/shahbaz/Research/Software/Spyder_ws/gps/yumi_model/right_arm/right_link_5_v.stl"/>
      </geometry>
      <origin rpy="0 0 0" xyz="0 0 0"/>
    </collision>

    <inertial>
      <mass value="0.330"/>
      <origin xyz="0.04991 0.0157 -0.00572" rpy="0 0 0"/>
      <inertia ixx="0.000279" ixy="0.000226" ixz="-0.000111" iyy="0.000797" iyz="-0.00002779" izz="0.000867"/>
    </inertial>

  </link>


  <link name="right_link_6">

    <visual>
      <geometry>
        <mesh filename="/home/shahbaz/Research/Software/Spyder_ws/gps/yumi_model/right_arm/right_link_6_v.stl"/>
      </geometry>
      <origin rpy="0 0 0" xyz="0 0 0"/>
      <material name="gray">
        <color rgba="0.5 0.5 0.5 1.0"/>
      </material>
    </visual>

    <collision>
      <geometry>
        <mesh filename="/home/shahbaz/Research/Software/Spyder_ws/gps/yumi_model/right_arm/right_link_6_v.stl"/>
      </geometry>
      <origin rpy="0 0 0" xyz="0 0 0"/>
    </collision>

    <inertial>
      <mass value="0.357"/>
      <origin xyz="-0.00923 -0.00415 0.0106" rpy="0 0 0"/>
      <inertia ixx="0.000298" ixy="-0.00000785" ixz="-0.0000247" iyy="0.000284" iyz="0.0000131" izz="0.000292"/>
    </inertial>

  </link>


  <link name="right_link_7">

    <visual>
      <geometry>
        <mesh filename="/home/shahbaz/Research/Software/Spyder_ws/gps/yumi_model/right_arm/right_link_7_v.stl"/>
      </geometry>
      <origin rpy="0 0 0" xyz="0 0 0"/>
      <material name="gray">
        <color rgba="0.5 0.5 0.5 1.0"/>
      </material>
    </visual>

    <collision>
      <geometry>
        <mesh filename="/home/shahbaz/Research/Software/Spyder_ws/gps/yumi_model/right_arm/right_link_7_v.stl"/>
      </geometry>
      <origin rpy="0 0 0" xyz="0 0 0"/>
    </collision>

    <inertial>
      <mass value="0.072"/>
      <origin xyz="-0.01667 -0.00147 0.00026" rpy="0 0 0"/>
      <inertia ixx="0.0000201" ixy="0.00000262" ixz="-0.000000481" iyy="0.0000295" iyz="0.000000413" izz="0.0000279"/>
    </inertial>

  </link>




  <link name="right_tool0">
    <!-- <inertial>
      <mass value="0.001"/>
      <inertia ixx="0.00000561" ixy="0.000000101" ixz="-0.00000113" iyy="0.00000545" iyz="-0.000000180" izz="0.00000289"/>
    </inertial-->
  </link>


  <joint name="right_joint_1" type="revolute">
    <parent link="base_link"/>
    <child link="right_link_1"/>
    <origin xyz="0.0476 -0.07  0.4115" rpy="0.9791 0.5692 0.8254"/>
    <axis xyz="0.0                   0.0                   1.0"/>
    <limit effort="10.0" lower="-2.92342649709" upper="2.92342649709" velocity="3.14159265359"/>
    <dynamics damping="1.06" friction="2.43"/>
  </joint>

  <joint name="right_joint_2" type="revolute">
    <parent link="right_link_1"/>
    <child link="right_link_2"/>
    <origin xyz="-0.03            0                      0.1075"/>
    <axis xyz="0.0                   1.0                  0.0"/>
    <limit effort="10.0" lower="-2.48709418409" upper="0.741764932098" velocity="3.14159265359"/>
    <dynamics damping="1.09" friction="2.76"/>
  </joint>

  <joint name="right_joint_3" type="revolute">
    <parent link="right_link_2"/>
    <child link="right_link_3"/>
    <origin xyz="0.03            0                      0.1603"/>
    <axis xyz="0.0 0.0 1.0"/>
    <limit effort="10.0" lower="-2.92342649709" upper="2.92342649709" velocity="3.14159265359"/>
    <dynamics damping="0.61" friction="1.11"/>
  </joint>

  <joint name="right_joint_4" type="revolute">
    <parent link="right_link_3"/>
    <child link="right_link_4"/>
    <origin xyz="0.0405                      0.0                      0.0912"/>
    <axis xyz="0.0                   1.0                  0.0"/>
    <limit effort="10.0" lower="-2.13802833369" upper="1.37881010908" velocity="3.14159265359"/>
    <dynamics damping="0.08" friction="0.52"/>
  </joint>

  <joint name="right_joint_5" type="revolute">
    <parent link="right_link_4"/>
    <child link="right_link_5"/>
    <origin xyz="0.1396 0.0 0.0405"/>
    <axis xyz="1.0 0.0 0.0"/>
    <limit effort="10.0" lower="-5.04400153826" upper="5.04400153826" velocity="6.98131700798"/>
    <dynamics damping="0.08" friction="0.52"/>
  </joint>

  <joint name="right_joint_6" type="revolute">
    <parent link="right_link_5"/>
    <child link="right_link_6"/>
    <origin xyz="0.1254 0.0 -0.027"/>
    <axis xyz="0.0                   1.0                  0.0"/>
    <limit effort="10.0" lower="-1.51843644924" upper="2.39110107523" velocity="6.98131700798"/>
    <dynamics damping="0.08" friction="0.52"/>
  </joint>

  <joint name="right_joint_7" type="revolute">
    <parent link="right_link_6"/>
    <child link="right_link_7"/>
    <origin xyz="0.036 0.0 0.027"/>
    <axis xyz="1.0 0.0 0.0"/>
    <limit effort="10.0" lower="-3.97935069455" upper="3.97935069455" velocity="6.98131700798"/>
    <dynamics damping="0.52" friction="1.0"/>
  </joint>

  <joint name="right_joint_7-tool0" type="fixed">
    <origin xyz="0.0 0.0 0.005"/>
    <parent link="right_link_7"/>
    <child link="right_tool0"/>
  </joint>


  <link name="right_gripper_base">
    <visual>
      <geometry>
        <mesh filename="/home/shahbaz/Research/Software/Spyder_ws/gps/yumi_model/gripper/smart_gripper_c.stl"/>
      </geometry>
      <origin rpy="0 0 0" xyz="0 0 0"/>
      <material name="gray">
        <color rgba="0.5 0.5 0.5 1.0"/>
      </material>
    </visual>
    <collision>
      <geometry>
        <mesh filename="/home/shahbaz/Research/Software/Spyder_ws/gps/yumi_model/gripper/smart_gripper_v.stl"/>
      </geometry>
      <origin rpy="0 0 0" xyz="0 0 0"/>
    </collision>
  </link>
  <joint name="right_gripper_base_joint" type="fixed">
    <parent link="right_tool0"/>
    <child link="right_gripper_base"/>
    <origin xyz="0.0                       0.0                       0.0"/>
  </joint>

  <!-- Left arm -->
  <link name="left_link_1">

    <visual>
      <geometry>
        <mesh filename="/home/shahbaz/Research/Software/Spyder_ws/gps/yumi_model/left_arm/left_link_1_v.stl"/>
      </geometry>
      <origin rpy="0 0 0" xyz="0 0 0"/>
      <material name="gray">
        <color rgba="0.5 0.5 0.5 1.0"/>
      </material>
    </visual>

    <collision>
      <geometry>
        <mesh filename="/home/shahbaz/Research/Software/Spyder_ws/gps/yumi_model/left_arm/left_link_1_v.stl"/>
      </geometry>
      <!-- <origin rpy="0 0 0" xyz="0 0 0"/> -->
      <!-- <origin rpy="0 0 0" xyz="-0.01993 0.00837 -0.01153"/> -->
      <!-- <origin rpy="-0.18425132041591932 -0.9506628417679347 -0.6292507964459597" xyz="-0.01993 0.00837 -0.01153"/> -->
      <origin rpy="-0.18425132041591932 -0.9506628417679347 -0.6292507964459597" xyz="-0.01993 0.00837 -0.01153"/>
    </collision>

    <inertial>
	  <origin xyz="-0.01468 -0.00021 0.06646" rpy="0 0 0"/>
      <mass value="1.753"/>
      <inertia ixx="0.00561" ixy="0.000101" ixz="-0.00113" iyy="0.00545" iyz="-0.000180" izz="0.00289"/>
    </inertial>

  </link>

<link name="left_link_2">
    <visual>
      <geometry>
        <mesh filename="/home/shahbaz/Research/Software/Spyder_ws/gps/yumi_model/left_arm/left_link_2_v.stl"/>
      </geometry>
      <origin rpy="0 0 0" xyz="0 0 0"/>
      <material name="gray">
        <color rgba="0.5 0.5 0.5 1.0"/>
      </material>
    </visual>
    <collision>
      <geometry>
        <mesh filename="/home/shahbaz/Research/Software/Spyder_ws/gps/yumi_model/left_arm/left_link_2_v.stl"/>
      </geometry>
      <origin rpy="0 0 0" xyz="0 0 0"/>
    </collision>

    <inertial>
      <mass value="1.444"/>
      <origin xyz="0.01828 -0.0177 0.06202" rpy="0 0 0"/>
      <inertia ixx="0.00743" ixy="0.000359" ixz="0.00106" iyy="0.00718" iyz="0.000143" izz="0.00225"/>
    </inertial>

  </link>


  <link name="left_link_3">
    <visual>
      <geometry>
        <mesh filename="/home/shahbaz/Research/Software/Spyder_ws/gps/yumi_model/left_arm/left_link_3_v.stl"/>
      </geometry>
      <origin rpy="0 0 0" xyz="0 0 0"/>
      <material name="gray">
        <color rgba="0.5 0.5 0.5 1.0"/>
      </material>
    </visual>
    <collision>
      <geometry>
        <mesh filename="/home/shahbaz/Research/Software/Spyder_ws/gps/yumi_model/left_arm/left_link_3_v.stl"/>
      </geometry>
      <origin rpy="0 0 0" xyz="0 0 0"/>
    </collision>

    <inertial>
      <mass value="0.936"/>
      <origin xyz="0.02349 0.00556 0.05944" rpy="0 0 0"/>
      <inertia ixx="0.00251" ixy="0.00000263" ixz="0.000688" iyy="0.00241" iyz="0.000089" izz="0.00143"/>
    </inertial>

  </link>

  <link name="left_link_4">

    <visual>
      <geometry>
        <mesh filename="/home/shahbaz/Research/Software/Spyder_ws/gps/yumi_model/left_arm/left_link_4_v.stl"/>
      </geometry>
      <origin rpy="0 0 0" xyz="0 0 0"/>
      <material name="gray">
        <color rgba="0.5 0.5 0.5 1.0"/>
      </material>
    </visual>

    <collision>
      <geometry>
        <mesh filename="/home/shahbaz/Research/Software/Spyder_ws/gps/yumi_model/left_arm/left_link_4_v.stl"/>
      </geometry>
      <origin rpy="0 0 0" xyz="0 0 0"/>
    </collision>

    <inertial>
      <mass value="0.723"/>
      <origin xyz="0.05385 -0.01612 0.02336" rpy="0 0 0"/>
      <inertia ixx="0.00108" ixy="0.000575" ixz="0.000633" iyy="0.00277" iyz="0.000203" izz="0.00280"/>
    </inertial>

  </link>

  <link name="left_link_5">
    <visual>
      <geometry>
        <mesh filename="/home/shahbaz/Research/Software/Spyder_ws/gps/yumi_model/left_arm/left_link_5_v.stl"/>
      </geometry>
      <origin rpy="0 0 0" xyz="0 0 0"/>
      <material name="gray">
        <color rgba="0.5 0.5 0.5 1.0"/>
      </material>
    </visual>
    <collision>
      <geometry>
        <mesh filename="/home/shahbaz/Research/Software/Spyder_ws/gps/yumi_model/left_arm/left_link_5_v.stl"/>
      </geometry>
      <origin rpy="0 0 0" xyz="0 0 0"/>
    </collision>

    <inertial>
      <mass value="0.330"/>
      <origin xyz="0.04991 0.0157 -0.00572" rpy="0 0 0"/>
      <inertia ixx="0.000279" ixy="0.000226" ixz="-0.000111" iyy="0.000797" iyz="-0.00002779" izz="0.000867"/>
    </inertial>

  </link>


  <link name="left_link_6">

    <visual>
      <geometry>
        <mesh filename="/home/shahbaz/Research/Software/Spyder_ws/gps/yumi_model/left_arm/left_link_6_v.stl"/>
      </geometry>
      <origin rpy="0 0 0" xyz="0 0 0"/>
      <material name="gray">
        <color rgba="0.5 0.5 0.5 1.0"/>
      </material>
    </visual>

    <collision>
      <geometry>
        <mesh filename="/home/shahbaz/Research/Software/Spyder_ws/gps/yumi_model/left_arm/left_link_6_v.stl"/>
      </geometry>
      <origin rpy="0 0 0" xyz="0 0 0"/>
    </collision>

    <inertial>
      <mass value="0.357"/>
      <origin xyz="-0.00923 -0.00415 0.0106" rpy="0 0 0"/>
      <inertia ixx="0.000298" ixy="-0.00000785" ixz="-0.0000247" iyy="0.000284" iyz="0.0000131" izz="0.000292"/>
    </inertial>

  </link>


  <link name="left_link_7">

    <visual>
      <geometry>
        <mesh filename="/home/shahbaz/Research/Software/Spyder_ws/gps/yumi_model/left_arm/left_link_7_v.stl"/>
      </geometry>
      <origin rpy="0 0 0" xyz="0 0 0"/>
      <material name="gray">
        <color rgba="0.5 0.5 0.5 1.0"/>
      </material>
    </visual>

    <collision>
      <geometry>
        <mesh filename="/home/shahbaz/Research/Software/Spyder_ws/gps/yumi_model/left_arm/left_link_7_v.stl"/>
      </geometry>
      <origin rpy="0 0 0" xyz="0 0 0"/>
    </collision>

    <inertial>
      <mass value="0.072"/>
      <origin xyz="-0.01667 -0.00147 0.00026" rpy="0 0 0"/>
      <inertia ixx="0.0000201" ixy="0.00000262" ixz="-0.000000481" iyy="0.0000295" iyz="0.000000413" izz="0.0000279"/>
    </inertial>

  </link>




  <link name="left_tool0">
    <!-- <inertial>
      <mass value="0.001"/>
      <inertia ixx="0.00000561" ixy="0.000000101" ixz="-0.00000113" iyy="0.00000545" iyz="-0.000000180" izz="0.00000289"/>
    </inertial-->
  </link>


  <joint name="left_joint_1" type="revolute">
    <parent link="base_link"/>
    <child link="left_link_1"/>
    <origin xyz="0.0476 0.07  0.4115" rpy="-0.9790814170822807 0.5692132849663647 -0.8254176948094931"/>
    <axis xyz="0.0                   0.0                   1.0"/>
    <limit effort="10.0" lower="-2.92342649709" upper="2.92342649709" velocity="3.14159265359"/>
    <dynamics damping="1.06" friction="2.43"/>
  </joint>

  <joint name="left_joint_2" type="revolute">
    <parent link="left_link_1"/>
    <child link="left_link_2"/>
    <origin xyz="-0.03            0                      0.1075"/>
    <axis xyz="0.0                   1.0                  0.0"/>
    <limit effort="10.0" lower="-2.48709418409" upper="0.741764932098" velocity="3.14159265359"/>
    <dynamics damping="1.09" friction="2.76"/>
  </joint>

  <joint name="left_joint_3" type="revolute">
    <parent link="left_link_2"/>
    <child link="left_link_3"/>
    <origin xyz="0.03            0                      0.1603"/>
    <axis xyz="0.0 0.0 1.0"/>
    <limit effort="10.0" lower="-2.92342649709" upper="2.92342649709" velocity="3.14159265359"/>
    <dynamics damping="0.61" friction="1.11"/>
  </joint>

  <joint name="left_joint_4" type="revolute">
    <parent link="left_link_3"/>
    <child link="left_link_4"/>
    <origin xyz="0.0405                      0.0                      0.0912"/>
    <axis xyz="0.0                   1.0                  0.0"/>
    <limit effort="10.0" lower="-2.13802833369" upper="1.37881010908" velocity="3.14159265359"/>
    <dynamics damping="0.08" friction="0.52"/>
  </joint>

  <joint name="left_joint_5" type="revolute">
    <parent link="left_link_4"/>
    <child link="left_link_5"/>
    <origin xyz="0.1396 0.0 0.0405"/>
    <axis xyz="1.0 0.0 0.0"/>
    <limit effort="10.0" lower="-5.04400153826" upper="5.04400153826" velocity="6.98131700798"/>
    <dynamics damping="0.08" friction="0.52"/>
  </joint>

  <joint name="left_joint_6" type="revolute">
    <parent link="left_link_5"/>
    <child link="left_link_6"/>
    <origin xyz="0.1254 0.0 -0.027"/>
    <axis xyz="0.0                   1.0                  0.0"/>
    <limit effort="10.0" lower="-1.51843644924" upper="2.39110107523" velocity="6.98131700798"/>
    <dynamics damping="0.08" friction="0.52"/>
  </joint>

  <joint name="left_joint_7" type="revolute">
    <parent link="left_link_6"/>
    <child link="left_link_7"/>
    <origin xyz="0.036 0.0 0.027"/>
    <axis xyz="1.0 0.0 0.0"/>
    <limit effort="10.0" lower="-3.97935069455" upper="3.97935069455" velocity="6.98131700798"/>
    <dynamics damping="0.52" friction="1.0"/>
  </joint>

  <joint name="left_joint_7-tool0" type="fixed">
    <origin xyz="0.0 0.0 0.005"/>
    <parent link="left_link_7"/>
    <child link="left_tool0"/>
  </joint>


  <link name="left_gripper_base">
    <visual>
      <geometry>
        <mesh filename="/home/shahbaz/Research/Software/Spyder_ws/gps/yumi_model/gripper/smart_gripper_c.stl"/>
      </geometry>
      <origin rpy="0 0 0" xyz="0 0 0"/>
      <material name="gray">
        <color rgba="0.5 0.5 0.5 1.0"/>
      </material>
    </visual>
    <collision>
      <geometry>
        <mesh filename="/home/shahbaz/Research/Software/Spyder_ws/gps/yumi_model/gripper/smart_gripper_v.stl"/>
      </geometry>
      <origin rpy="0 0 0" xyz="0 0 0"/>
    </collision>
  </link>
  <joint name="left_gripper_base_joint" type="fixed">
    <parent link="left_tool0"/>
    <child link="left_gripper_base"/>
    <origin xyz="0.0                       0.0                       0.0"/>
  </joint>
</robot>
